<?xml version="1.0"?>
<robot name="Manipulator_arm">
    <link name="world"/>
        <link name="base_link">
            <inertial>
                <origin xyz="0.0 0.0 0.0025" rpy="0.0 0.0 0.0"/>
                <mass value="1.0"/>
                <inertia ixx="27" ixy="0.0" ixz="0.0" iyy="0.005" iyz="0.0" izz="0.0027"/>
            </inertial>
            <visual>
                <origin xyz="0.0 0.0 0.0025" rpy="0.0 0.0 0.0"/>
                <geometry>
                    <box size="0.15 0.15 0.005"/>
                </geometry>
                <material name="red">
                    <color rgba="1.0 0.0 0.0 1.0"/>
                </material>
            </visual>
            <collision>
                <origin xyz="0.0 0.0 0.0025" rpy="0.0 0.0 0.0"/>
                <geometry>
                    <box size="0.15 0.15 0.005"/>
                </geometry>
            </collision>
        </link>

    <joint name="joint" type="fixed">
        <parent link="world"/>
        <child link="base_link"/>
    </joint>


    <link name="link1">
        <inertial>
            <origin xyz="0.0 0.0 0.022" rpy="0.0 0.0 0.0"/>
            <mass value="0.001"/>
            <inertia ixx="27" ixy="0.0" ixz="0.0" iyy="0.005" iyz="0.0" izz="0.0027"/>
        </inertial>
        <visual>
            <origin xyz="0.0 0.0 0.022" rpy="0.0 0.0 0.0"/>
            <geometry>
                <box size="0.15 0.15 0.044"/>
            </geometry>
            <material name="red">
                <color rgba="1.0 0.0 0.0 1.0"/>
            </material>
        </visual>
        <collision>
            <origin xyz="0.0 0.0 0.022" rpy="0.0 0.0 0.0"/>
            <geometry>
                <box size="0.15 0.15 0.044"/>
            </geometry>
        </collision>
    </link>

    <joint name="joint1" type="fixed">
        <parent link="base_link"/>
        <child link="link1"/>
    </joint>


    
    
    <link name="link2">
        <inertial>
            <origin xyz="0.0 0.0 0.0125" rpy="0.0 0.0 0.0"/>
            <mass value="0.001"/>
            <inertia ixx="27" ixy="0.0" ixz="0.0" iyy="0.005" iyz="0.0" izz="0.0027"/>
        </inertial>
        <visual>
            <origin xyz="0.0 0.0 0.0125" rpy="0.0 0.0 0.0"/>
            <geometry>
                <box size="0.075 0.075 0.025"/>
            </geometry>
            <material name="red">
                <color rgba="1.0 0.0 0.0 1.0"/>
            </material>
        </visual>
        <collision>
            <origin xyz="0.0 0.0 0.0125" rpy="0.0 0.0 0.0"/>
            <geometry>
                <box size="0.075 0.075 0.025"/>
            </geometry>
        </collision>
    </link>

    <joint name="joint2" type="revolute">
        <origin xyz="0.0 0.0 0.044" rpy="0.0 0.0 0.0"/>
        <parent link="link1"/>
        <child link="link2"/>
        <axis xyz="0.0 0.0 1.0"/>
        <limit lower="0.0" upper="3.14" effort="0.0" velocity="0.0" />
    </joint>

    <transmission name="trans1">
       <type>transmission_interface/SimpleTransmission</type>
       <actuator name="motor1">
         <mechanicalReduction>1</mechanicalReduction>
       </actuator>
       <joint name="joint2">
         <hardwareInterface>PositionJointInterface</hardwareInterface>
       </joint>
    </transmission>



    <link name="link3">
        <inertial>
            <origin xyz="0.0 0.0 0.0165" rpy="0.0 0.0 0.0"/>
            <mass value="0.005"/>
            <inertia ixx="27" ixy="0.0" ixz="0.0" iyy="0.005" iyz="0.0" izz="0.0027"/>
        </inertial>
        <visual>
            <origin xyz="0.0 0.0 0.0165" rpy="0.0 0.0 0.0"/>
            <geometry>
                <box size="0.04 0.065 0.033"/>
            </geometry>
            <material name="Red">
                <color rgba="1.0 0.0 0.0 1.0"/>
            </material>
        </visual>
        <collision>
            <origin xyz="0.0 0.0 0.0165" rpy="0.0 0.0 0.0"/>
            <geometry>
                <box size="0.04 0.065 0.033"/>
            </geometry>
        </collision>
    </link>

    <joint name="joint3" type="fixed">
        <origin xyz="0.0 0.0 0.025" rpy="0.0 0.0 0.0"/>
        <parent link="link2"/>
        <child link="link3"/>
    </joint>

    




    <link name="link4">
        <inertial>
            <origin xyz="0.0 0.0 0.07" rpy="0.0 0.0 0.0"/>
            <mass value="0.001"/>
            <inertia ixx="27" ixy="0.0" ixz="0.0" iyy="0.005" iyz="0.0" izz="0.0027"/>
        </inertial>
        <visual>
            <origin xyz="0.0 0.0 0.07" rpy="0.0 0.0 0.0"/>
            <geometry>
                <box size="0.025 0.006 0.14"/>
            </geometry>
            <material name="blue">
                <color rgba="0.0 0.0 1.0 1.0"/>
            </material>
        </visual>
        <collision>
            <origin xyz="0.0 0.0 0.07" rpy="0.0 0.0 0.0"/>
            <geometry>
                <box size="0.025 0.006 0.14"/>
            </geometry>
        </collision>
    </link>

    <joint name="joint4" type="revolute">
        <origin xyz="0.013 0.0325 0.02" rpy="0.0 0.0 0.0"/>
        <parent link="link3"/>
        <child link="link4"/>
        <axis xyz="0.0 1.0 0.0"/>
        <limit lower="-1.57" upper="1.57" effort="0.0" velocity="0.0"/>
    </joint>

    <transmission name="trans2">
       <type>transmission_interface/SimpleTransmission</type>
       <actuator name="motor2">
         <mechanicalReduction>1</mechanicalReduction>
       </actuator>
       <joint name="joint4">
         <hardwareInterface>PositionJointInterface</hardwareInterface>
       </joint>
    </transmission>




    <link name="link5">
        <inertial>
            <origin xyz="0.0 0.0 0.003" rpy="0.0 0.0 0.0"/>
            <mass value="0.0001"/>
            <inertia ixx="27" ixy="0.0" ixz="0.0" iyy="0.005" iyz="0.0" izz="0.0027"/>
        </inertial>
        <visual>
            <origin xyz="0.0 0.0 0.003" rpy="0.0 0.0 0.0"/>
            <geometry>
                <box size="0.06 0.105 0.006"/>
            </geometry>
            <material name="red">
                <color rgba="1.0 0.0 0.0 1.0"/>
            </material>
        </visual>
        <collision>
            <origin xyz="0.0 0.0 0.003" rpy="0.0 0.0 0.0"/>
            <geometry>
                <box size="0.06 0.105 0.006"/>
            </geometry>
        </collision>
    </link>

    <joint name="joint5" type="fixed">
        <origin xyz="0.0 -0.045 0.14" rpy="0.0 0.0 0.0"/>
        <parent link="link4"/>
        <child link="link5"/>
    </joint> 




    <link name="link6">
        <inertial>
            <origin xyz="0.0 0.0 0.0165" rpy="0.0 0.0 0.0"/>
            <mass value="0.005"/>
            <inertia ixx="27" ixy="0.0" ixz="0.0" iyy="0.005" iyz="0.0" izz="0.0027"/>
        </inertial>
        <visual>
            <origin xyz="0.0 0.0 0.0165" rpy="0.0 0.0 0.0"/>
            <geometry>
                <box size="0.04 0.065 0.033"/>
            </geometry>
            <material name="Red">
                <color rgba="1.0 0.0 0.0 1.0"/>
            </material>
        </visual>
        <collision>
            <origin xyz="0.0 0.0 0.0165" rpy="0.0 0.0 0.0"/>
            <geometry>
                <box size="0.04 0.065 0.033"/>
            </geometry>
        </collision>
    </link>

    <joint name="joint6" type="fixed">
        <origin xyz="0.0 0.0 0.006" rpy="0.0 0.0 0.0"/>
        <parent link="link5"/>
        <child link="link6"/>
    </joint>





    <link name="link7">
        <inertial>
            <origin xyz="0.0 0.0 0.035" rpy="0.0 0.0 0.0"/>
            <mass value="0.001"/>
            <inertia ixx="27" ixy="0.0" ixz="0.0" iyy="0.005" iyz="0.0" izz="0.0027"/>
        </inertial>
        <visual>
            <origin xyz="0.0 0.0 0.035" rpy="0.0 0.0 0.0"/>
            <geometry>
                <box size="0.025 0.006 0.07"/>
            </geometry>
            <material name="blue">
                <color rgba="0.0 0.0 1.0 1.0"/>
            </material>
        </visual>
        <collision>
            <origin xyz="0.0 0.0 0.035" rpy="0.0 0.0 0.0"/>
            <geometry>
                <box size="0.025 0.006 0.07"/>
            </geometry>
        </collision>
    </link>

    <joint name="joint7" type="revolute">
        <origin xyz="0.013 -0.0325 0.03" rpy="0.0 0.0 0.0"/>
        <parent link="link6"/>
        <child link="link7"/>
        <axis xyz="0.0 1.0 0.0"/>
        <limit lower="-1.57" upper="1.57" effort="0.0" velocity="0.0"/>
    </joint>

    <transmission name="trans3">
       <type>transmission_interface/SimpleTransmission</type>
       <actuator name="motor3">
         <mechanicalReduction>1</mechanicalReduction>
       </actuator>
       <joint name="joint7">
         <hardwareInterface>PositionJointInterface</hardwareInterface>
       </joint>
    </transmission>





    <link name="link8">
        <inertial>
            <origin xyz="0.0 0.0 0.003" rpy="0.0 0.0 0.0"/>
            <mass value="0.0001"/>
            <inertia ixx="27" ixy="0.0" ixz="0.0" iyy="0.005" iyz="0.0" izz="0.0027"/>
        </inertial>
        <visual>
            <origin xyz="0.0 0.0 0.003" rpy="0.0 0.0 0.0"/>
            <geometry>
                <box size="0.06 0.105 0.006"/>
            </geometry>
            <material name="red">
                <color rgba="1.0 0.0 0.0 1.0"/>
            </material>
        </visual>
        <collision>
            <origin xyz="0.0 0.0 0.003" rpy="0.0 0.0 0.0"/>
            <geometry>
                <box size="0.06 0.105 0.006"/>
            </geometry>
        </collision>
    </link>

    <joint name="joint8" type="fixed">
        <origin xyz="0.0 0.045 0.07" rpy="0.0 0.0 0.0"/>
        <parent link="link7"/>
        <child link="link8"/>
    </joint>





    <link name="link9">
        <inertial>
            <origin xyz="0.0 0.0 0.0165" rpy="0.0 0.0 0.0"/>
            <mass value="0.005"/>
            <inertia ixx="27" ixy="0.0" ixz="0.0" iyy="0.005" iyz="0.0" izz="0.0027"/>
        </inertial>
        <visual>
            <origin xyz="0.0 0.0 0.0165" rpy="0.0 0.0 0.0"/>
            <geometry>
                <box size="0.04 0.065 0.033"/>
            </geometry>
            <material name="Red">
                <color rgba="1.0 0.0 0.0 1.0"/>
            </material>
        </visual>
        <collision>
            <origin xyz="0.0 0.0 0.0165" rpy="0.0 0.0 0.0"/>
            <geometry>
                <box size="0.04 0.065 0.033"/>
            </geometry>
        </collision>
    </link>

    <joint name="joint9" type="fixed">
        <origin xyz="0.0 0.0 0.006" rpy="0.0 0.0 0.0"/>
        <parent link="link8"/>
        <child link="link9"/>
    </joint>





    <link name="link10">
        <inertial>
            <origin xyz="0.0 0.0 0.0225" rpy="0.0 0.0 0.0"/>
            <mass value="0.001"/>
            <inertia ixx="27" ixy="0.0" ixz="0.0" iyy="0.005" iyz="0.0" izz="0.0027"/>
        </inertial>
        <visual>
            <origin xyz="0.0 0.0 0.0225" rpy="0.0 0.0 0.0"/>
            <geometry>
                <box size="0.025 0.006 0.051"/>
            </geometry>
            <material name="blue">
                <color rgba="0.0 0.0 1.0 1.0"/>
            </material>
        </visual>
        <collision>
            <origin xyz="0.0 0.0 0.0225" rpy="0.0 0.0 0.0"/>
            <geometry>
                <box size="0.025 0.006 0.051"/>
            </geometry>
        </collision>
    </link>

    <joint name="joint10" type="revolute">
        <origin xyz="0.013 0.0325 0.02" rpy="0.0 0.0 0.0"/>
        <parent link="link9"/>
        <child link="link10"/>
        <axis xyz="0.0 1.0 0.0"/>
        <limit lower="-1.57" upper="1.57" effort="0.0" velocity="0.0"/>
    </joint>

    <transmission name="trans4">
       <type>transmission_interface/SimpleTransmission</type>
       <actuator name="motor4">
         <mechanicalReduction>1</mechanicalReduction>
       </actuator>
       <joint name="joint10">
         <hardwareInterface>PositionJointInterface</hardwareInterface>
       </joint>
    </transmission>





    <link name="link11">
        <inertial>
            <origin xyz="0.0 0.0 0.003" rpy="0.0 0.0 0.0"/>
            <mass value="0.0001"/>
            <inertia ixx="27" ixy="0.0" ixz="0.0" iyy="0.005" iyz="0.0" izz="0.0027"/>
        </inertial>
        <visual>
            <origin xyz="0.0 0.0 0.003" rpy="0.0 0.0 0.0"/>
            <geometry>
                <box size="0.06 0.075 0.006"/>
            </geometry>
            <material name="red">
                <color rgba="1.0 0.0 0.0 1.0"/>
            </material>
        </visual>
        <collision>
            <origin xyz="0.0 0.0 0.003" rpy="0.0 0.0 0.0"/>
            <geometry>
                <box size="0.06 0.075 0.006"/>
            </geometry>
        </collision>
    </link>

    <joint name="joint11" type="fixed">
        <origin xyz="0.0 -0.035 0.050" rpy="0.0 0.0 0.0"/>
        <parent link="link10"/>
        <child link="link11"/>
    </joint> 





    <link name="link12">
        <inertial>
            <origin xyz="0.0 0.0 0.0575" rpy="0.0 0.0 0.0"/>
            <mass value="0.05"/>
            <inertia ixx="27" ixy="0.0" ixz="0.0" iyy="0.005" iyz="0.0" izz="0.0027"/>
        </inertial>
        <visual>
            <origin xyz="0.0 0.0 0.0575" rpy="0.0 0.0 0.0"/>
            <geometry>
                <cylinder radius="0.01" length="0.115"/>
            </geometry>
            <material name="green">
                <color rgba="0.0 1.0 0.0 1.0"/>
            </material>
        </visual>
        <collision>
            <origin xyz="0.0 0.0 0.0575" rpy="0.0 0.0 0.0"/>
            <geometry>
                <cylinder radius="0.01" length="0.115"/>
            </geometry>
        </collision>
    </link>

    <joint name="joint12" type="fixed">
        <origin xyz="0.0 0.0 0.006" rpy="0.0 0.0 0.0"/>
        <parent link="link11"/>
        <child link="link12"/>
    </joint>-->


    <gazebo>
       <plugin name="gazebo_ros_control" filename="libgazebo_ros_control.so">
         <robotNamespace>/</robotNamespace>
       </plugin>
    </gazebo>

    <gazebo>
      <plugin name="joint_state_publisher" filename="libgazebo_ros_joint_state_publisher">
        <jointName>joint1</jointName>
      </plugin>  
    </gazebo>
</robot>